Workbook

Sheet Template FIX
A1: Nama Barang | B1: Kode | C1: Unit | D1: Kuantitas | E1: Harga jual | F1: Gudang
A2: ATAP 2 SSN BAMBU COKLAT GGROOF (RUSAK) | B2: 102097 | C2: LEMBAR | D2: =VLOOKUP(B2,'HASIL REKAP OPNAME 2'!$B$2:$F$917,4,0) -> 16 | E2: 10000 | F2: GUDANG PALANGKARAYA
A3: ATAP 2 SSN 0.30 HITAM MATTE | B3: 102043 | C3: LEMBAR | D3: =VLOOKUP(B3,'HASIL REKAP OPNAME 2'!$B$2:$F$917,4,0) -> 50 | E3: 10000 | F3: GUDANG PALANGKARAYA
A4: ATAP 2 SSN COKLAT ARRU ROOF | B4: 100975 | C4: LEMBAR | D4: =VLOOKUP(B4,'HASIL REKAP OPNAME 2'!$B$2:$F$917,4,0) -> 90 | E4: 10000 | F4: GUDANG PALANGKARAYA
A5: ATAP 2 SSN COKLAT ARRU ROOF (RUSAK) | B5: 102196 | C5: LEMBAR | D5: =VLOOKUP(B5,'HASIL REKAP OPNAME 2'!$B$2:$F$917,4,0) -> 6 | E5: 10000 | F5: GUDANG PALANGKARAYA
A6: ATAP 2 SSN COKLAT DYNASTY (RUSAK) | B6: 102198 | C6: LEMBAR | D6: =VLOOKUP(B6,'HASIL REKAP OPNAME 2'!$B$2:$F$917,4,0) -> 2 | E6: 10000 | F6: GUDANG PALANGKARAYA
A7: ATAP 2 SSN COKLAT MAHKOTA | B7: 100979 | C7: LEMBAR | D7: =VLOOKUP(B7,'HASIL REKAP OPNAME 2'!$B$2:$F$917,4,0) -> 6 | E7: 10000 | F7: GUDANG PALANGKARAYA
A8: ATAP 2 SSN COKLAT MAHKOTA (RUSAK) | B8: 102200 | C8: LEMBAR | D8: =VLOOKUP(B8,'HASIL REKAP OPNAME 2'!$B$2:$F$917,4,0) -> 3 | E8: 10000 | F8: GUDANG PALANGKARAYA
A9: ATAP 2 SSN MAROON GGROOF | B9: 100983 | C9: LEMBAR | D9: =VLOOKUP(B9,'HASIL REKAP OPNAME 2'!$B$2:$F$917,4,0) -> 3 | E9: 10000 | F9: GUDANG PALANGKARAYA
A10: ATAP 2 SSN MAROON GGROOF (RUSAK) | B10: 102204 | C10: LEMBAR | D10: =VLOOKUP(B10,'HASIL REKAP OPNAME 2'!$B$2:$F$917,4,0) -> 2 | E10: 10000 | F10: GUDANG PALANGKARAYA
A11: ATAP 2 SSN MERAH MAHKOTA | B11: 100984 | C11: LEMBAR | D11: =VLOOKUP(B11,'HASIL REKAP OPNAME 2'!$B$2:$F$917,4,0) -> 5 | E11: 10000 | F11: GUDANG PALANGKARAYA
A12: ATAP 2 SSN MERAH MAHKOTA (RUSAK) | B12: 102205 | C12: LEMBAR | D12: =VLOOKUP(B12,'HASIL REKAP OPNAME 2'!$B$2:$F$917,4,0) -> 2 | E12: 10000 | F12: GUDANG PALANGKARAYA
A13: ATAP 2 SSN PASIR KOKOROOF | B13: 100985 | C13: LEMBAR | D13: =VLOOKUP(B13,'HASIL REKAP OPNAME 2'!$B$2:$F$917,4,0) -> 1 | E13: 10000 | F13: GUDANG PALANGKARAYA
... A818: SPANDECK PASIR HITAM 0.30 x 6M KCNA | B818: 103504 | C818: LEMBAR | D818: =VLOOKUP(B818,'HASIL REKAP OPNAME 2'!$B$2:$F$917,4,0) -> 200 | E818: 10000 | F818: GUDANG PALANGKARAYA
A819: LIS WPC TW 917 / 3 M | B819: 103493 | D819: =VLOOKUP(B819,'HASIL REKAP OPNAME 2'!$B$2:$F$917,4,0) -> 7 | E819: 10000 | F819: GUDANG PALANGKARAYA
A820: NOK C PUTRI SAYAP BIRU | B820: 103513 | D820: =VLOOKUP(B820,'HASIL REKAP OPNAME 2'!$B$2:$F$917,4,0) -> 20 | E820: 10000 | F820: GUDANG PALANGKARAYA
A821: MARMER 120*240*0,3 CM GWB 020 HYI | B821: 102017 | C821: LEMBAR | D821: 2 | E821: 10000 | F821: GUDANG PALANGKARAYA
A822: MARMER 120*240*0,3 CM GWB 018 HYI | B822: 102012 | C822: LEMBAR | D822: 2 | E822: 10000 | F822: GUDANG PALANGKARAYA
A823: MARMER 120*240*0,3 CM GWB 007 HYI | B823: 103440 | C823: LEMBAR | D823: 2 | E823: 10000 | F823: GUDANG PALANGKARAYA
A824: MARMER 120*240*0,3 CM GWB 017 HYI | B824: 102045 | C824: LEMBAR | D824: 2 | E824: 10000 | F824: GUDANG PALANGKARAYA

Sheet Template
A1: Nama Barang | B1: Kode | C1: Unit | D1: Kuantitas | E1: Biaya Satuan | F1: Gudang | G1: Tipe Penyesuaian | H1: Nama Dept Barang | I1: No Proyek Barang
A2: ATAP 2 SSN BAMBU COKLAT GGROOF (RUSAK) | B2: 102097 | C2: LEMBAR | D2: 16 | E2: 0 | F2: GUDANG PALANGKARAYA | G2: Pengurangan
A3: ATAP 2 SSN 0.30 HITAM MATTE | B3: 102043 | C3: LEMBAR | D3: 50 | E3: 0 | F3: GUDANG PALANGKARAYA | G3: Pengurangan
A4: ATAP 2 SSN COKLAT ARRU ROOF | B4: 100975 | C4: LEMBAR | D4: 90 | E4: 0 | F4: GUDANG PALANGKARAYA | G4: Pengurangan
A5: ATAP 2 SSN COKLAT ARRU ROOF (RUSAK) | B5: 102196 | C5: LEMBAR | D5: 6 | E5: 0 | F5: GUDANG PALANGKARAYA | G5: Pengurangan
A6: ATAP 2 SSN COKLAT DYNASTY (RUSAK) | B6: 102198 | C6: LEMBAR | D6: 2 | E6: 0 | F6: GUDANG PALANGKARAYA | G6: Pengurangan
A7: ATAP 2 SSN COKLAT MAHKOTA | B7: 100979 | C7: LEMBAR | D7: 6 | E7: 20500 | F7: GUDANG PALANGKARAYA | G7: Penambahan
A8: ATAP 2 SSN COKLAT MAHKOTA (RUSAK) | B8: 102200 | C8: LEMBAR | D8: 3 | E8: 0 | F8: GUDANG PALANGKARAYA | G8: Pengurangan
A9: ATAP 2 SSN MAROON GGROOF | B9: 100983 | C9: LEMBAR | D9: 3 | E9: 20000 | F9: GUDANG PALANGKARAYA | G9: Penambahan
A10: ATAP 2 SSN MAROON GGROOF (RUSAK) | B10: 102204 | C10: LEMBAR | D10: 2 | E10: 0 | F10: GUDANG PALANGKARAYA | G10: Pengurangan
A11: ATAP 2 SSN MERAH MAHKOTA | B11: 100984 | C11: LEMBAR | D11: 5 | E11: 99500 | F11: GUDANG PALANGKARAYA | G11: Penambahan
A12: ATAP 2 SSN MERAH MAHKOTA (RUSAK) | B12: 102205 | C12: LEMBAR | D12: 2 | E12: 0 | F12: GUDANG PALANGKARAYA | G12: Pengurangan
A13: ATAP 2 SSN PASIR KOKOROOF | B13: 100985 | C13: LEMBAR | D13: 1 | E13: 0 | F13: GUDANG PALANGKARAYA | G13: Pengurangan
... A19: BAUT 10 X 16 PATTA | B19: 100999 | C19: KOTAK | D19: 1 | E19: 0 | F19: GUDANG PALANGKARAYA | G19: Pengurangan
A20: BAUT ATAP 12 X 45 SUPERDIL | B20: 101003 | C20: KOTAK | D20: 25 | E20: 96000 | F20: GUDANG PALANGKARAYA | G20: Penambahan | I20: s
A21: BAUT ATAP 12 X 50 SUPERDRILL | B21: 101004 | C21: KOTAK | D21: 39 | E21: 40000 | F21: GUDANG PALANGKARAYA | G21: Penambahan
A22: BAUT TASSO 10 X 16 LUMBA LUMBA | B22: 100998 | C22: KOTAK | D22: 38 | E22: 0 | F22: GUDANG PALANGKARAYA | G22: Pengurangan
A23: BAUT TASSO 10 X 16 LUMBA LUMBA (800 pcs) | B23: 103456 | C23: KOTAK | D23: 6 | E23: 0 | F23: GUDANG PALANGKARAYA | G23: Pengurangan
A24: BAUT TASSO 10 X 16 ONE FIX (1000 pcs) | B24: 103511 | C24: KOTAK | D24: 10 | E24: 0 | F24: GUDANG PALANGKARAYA | G24: Pengurangan
A25: C75-65 6M ARRU TRUSS (RUSAK) | B25: 102242 | C25: BATANG | D25: 1 | E25: 0 | F25: GUDANG PALANGKARAYA | G25: Pengurangan
A26: C75-65i 6 M ARRU (RUSAK) | B26: 102246 | C26: BATANG | D26: 1 | E26: 0 | F26: GUDANG PALANGKARAYA | G26: Pengurangan
A27: C75-75 ARU TRUSS | B27: 103382 | C27: BATANG | D27: 35 | E27: 0 | F27: GUDANG PALANGKARAYA | G27: Pengurangan
A28: C75-75 ECO ARU TRUSS | B28: 103383 | C28: BATANG | D28: 60 | E28: 0 | F28: GUDANG PALANGKARAYA | G28: Pengurangan
A29: DAK 54 / 4M (RUSAK) | B29: 102269 | C29: LEMBAR | D29: 4 | E29: 0 | F29: GUDANG PALANGKARAYA | G29: Pengurangan
A30: DYNABOLT 10 X 50 MARIO | B30: 101035 | C30: PCS | D30: 146 | E30: 0 | F30: GUDANG PALANGKARAYA | G30: Pengurangan
A31: DYNABOLT 10 X 65 MARIO | B31: 101036 | C31: PCS | D31: 452 | E31: 0 | F31: GUDANG PALANGKARAYA | G31: Pengurangan
A32: ELG 01 / 4 M | B32: 101038 | C32: LEMBAR | D32: 8 | E32: 36800 | F32: GUDANG PALANGKARAYA | G32: Penambahan
... A814: OR. 70 x 90 TIPE C (RIJECT) | B814: 301619 | C814: PCS | D814: 1 | E814: 370000 | F814: GUDANG PALANGKARAYA | G814: Penambahan
A815: ATAP 2 SSN 0,25 TANPA PASIR MINIMALIS KOKOROOF HITAM | B815: 103555 | C815: LEMBAR | D815: 1 | F815: GUDANG PALANGKARAYA | G815: Pengurangan
A816: LIS 07 A BESAR / 4 M | B816: 101488 | C816: BATANG | D816: 240 | E816: 30780 | F816: GUDANG PALANGKARAYA | G816: Pengurangan
A817: C75-75 6M ARRU TRUSS | B817: 101016 | C817: BATANG | D817: 250 | E817: 64000 | F817: GUDANG PALANGKARAYA | G817: Pengurangan
A818: SPANDECK PASIR HITAM 0.30 x 5M KCNA | B818: 103505 | C818: LEMBAR | D818: 100 | E818: 322175 | F818: GUDANG PALANGKARAYA | G818: Pengurangan
A819: SPANDECK PASIR HITAM 0.30 x 6M KCNA | B819: 103504 | C819: LEMBAR | D819: 200 | E819: 386610 | F819: GUDANG PALANGKARAYA | G819: Pengurangan
A820: LIS WPC TW 917 / 3 M | B820: 103493 | D820: 7 | E820: 26500 | F820: GUDANG PALANGKARAYA | G820: Penambahan
A821: MARMER 120*240*0,3 CM GWB 016 HYI | B821: 103439 | D821: 2 | E821: 260000 | F821: GUDANG PALANGKARAYA | G821: Penambahan
A822: NOK C PUTRI SAYAP BIRU | B822: 103513 | D822: 20 | E822: 12000 | F822: GUDANG PALANGKARAYA | G822: Penambahan

Sheet HASIL REKAP OPNAME 2
A1: Nama Barang | B1: KODE BARANG | C1: SATUAN | D1: QTY | F1: TIPE
A2: ATAP 2 SSN BAMBU COKLAT GGROOF (RUSAK) | B2: 102097 | C2: =VLOOKUP(B2,'Barang & Jasa'!$C$2:$D$4066,2,0) -> LEMBAR | D2: =VLOOKUP(B2,'REKAP OPNAME 2 '!$B$2:$G$909,6,0) -> -16 | E2: =ABS(D2) -> 16 | F2: =IF(D2<0, "Pengurangan", "Penambahan") -> Pengurangan
A3: ATAP 2 SSN 0.25 HITAM MATTE | B3: 102042 | C3: =VLOOKUP(B3,'Barang & Jasa'!$C$2:$D$4066,2,0) -> LEMBAR | D3: =VLOOKUP(B3,'REKAP OPNAME 2 '!$B$2:$G$909,6,0) -> 0 | E3: =ABS(D3) -> 0 | F3: =IF(D3<0, "Pengurangan", "Penambahan") -> Penambahan
A4: ATAP 2 SSN 0.30 HITAM MATTE | B4: 102043 | C4: =VLOOKUP(B4,'Barang & Jasa'!$C$2:$D$4066,2,0) -> LEMBAR | D4: =VLOOKUP(B4,'REKAP OPNAME 2 '!$B$2:$G$909,6,0) -> -50 | E4: =ABS(D4) -> 50 | F4: =IF(D4<0, "Pengurangan", "Penambahan") -> Pengurangan
A5: ATAP 2 SSN COKLAT ARRU ROOF | B5: 100975 | C5: =VLOOKUP(B5,'Barang & Jasa'!$C$2:$D$4066,2,0) -> LEMBAR | D5: =VLOOKUP(B5,'REKAP OPNAME 2 '!$B$2:$G$909,6,0) -> -90 | E5: =ABS(D5) -> 90 | F5: =IF(D5<0, "Pengurangan", "Penambahan") -> Pengurangan
A6: ATAP 2 SSN COKLAT ARRU ROOF (RUSAK) | B6: 102196 | C6: =VLOOKUP(B6,'Barang & Jasa'!$C$2:$D$4066,2,0) -> LEMBAR | D6: =VLOOKUP(B6,'REKAP OPNAME 2 '!$B$2:$G$909,6,0) -> -6 | E6: =ABS(D6) -> 6 | F6: =IF(D6<0, "Pengurangan", "Penambahan") -> Pengurangan
A7: ATAP 2 SSN COKLAT DYNASTY | B7: 100977 | C7: =VLOOKUP(B7,'Barang & Jasa'!$C$2:$D$4066,2,0) -> LEMBAR | D7: =VLOOKUP(B7,'REKAP OPNAME 2 '!$B$2:$G$909,6,0) -> 0 | E7: =ABS(D7) -> 0 | F7: =IF(D7<0, "Pengurangan", "Penambahan") -> Penambahan
A8: ATAP 2 SSN COKLAT DYNASTY (RUSAK) | B8: 102198 | C8: =VLOOKUP(B8,'Barang & Jasa'!$C$2:$D$4066,2,0) -> LEMBAR | D8: =VLOOKUP(B8,'REKAP OPNAME 2 '!$B$2:$G$909,6,0) -> -2 | E8: =ABS(D8) -> 2 | F8: =IF(D8<0, "Pengurangan", "Penambahan") -> Pengurangan
A9: ATAP 2 SSN COKLAT MAHKOTA | B9: 100979 | C9: =VLOOKUP(B9,'Barang & Jasa'!$C$2:$D$4066,2,0) -> LEMBAR | D9: =VLOOKUP(B9,'REKAP OPNAME 2 '!$B$2:$G$909,6,0) -> 6 | E9: =ABS(D9) -> 6 | F9: =IF(D9<0, "Pengurangan", "Penambahan") -> Penambahan
A10: ATAP 2 SSN COKLAT MAHKOTA (RUSAK) | B10: 102200 | C10: =VLOOKUP(B10,'Barang & Jasa'!$C$2:$D$4066,2,0) -> LEMBAR | D10: =VLOOKUP(B10,'REKAP OPNAME 2 '!$B$2:$G$909,6,0) -> -3 | E10: =ABS(D10) -> 3 | F10: =IF(D10<0, "Pengurangan", "Penambahan") -> Pengurangan
A11: ATAP 2 SSN MAROON GGROOF | B11: 100983 | C11: =VLOOKUP(B11,'Barang & Jasa'!$C$2:$D$4066,2,0) -> LEMBAR | D11: =VLOOKUP(B11,'REKAP OPNAME 2 '!$B$2:$G$909,6,0) -> 3 | E11: =ABS(D11) -> 3 | F11: =IF(D11<0, "Pengurangan", "Penambahan") -> Penambahan
A12: ATAP 2 SSN MAROON GGROOF (RUSAK) | B12: 102204 | C12: =VLOOKUP(B12,'Barang & Jasa'!$C$2:$D$4066,2,0) -> LEMBAR | D12: =VLOOKUP(B12,'REKAP OPNAME 2 '!$B$2:$G$909,6,0) -> -2 | E12: =ABS(D12) -> 2 | F12: =IF(D12<0, "Pengurangan", "Penambahan") -> Pengurangan
A13: ATAP 2 SSN MERAH MAHKOTA | B13: 100984 | C13: =VLOOKUP(B13,'Barang & Jasa'!$C$2:$D$4066,2,0) -> LEMBAR | D13: =VLOOKUP(B13,'REKAP OPNAME 2 '!$B$2:$G$909,6,0) -> 5 | E13: =ABS(D13) -> 5 | F13: =IF(D13<0, "Pengurangan", "Penambahan") -> Penambahan
... A909: OR. 70 x 90 TIPE C (RIJECT) | B909: 301619 | C909: =VLOOKUP(B909,'Barang & Jasa'!$C$2:$D$4066,2,0) -> PCS | D909: =VLOOKUP(B909,'REKAP OPNAME 2 '!$B$2:$G$909,6,0) -> 1 | E909: =ABS(D909) -> 1 | F909: =IF(D909<0, "Pengurangan", "Penambahan") -> Penambahan
A910: ATAP 2 SSN 0,25 TANPA PASIR MINIMALIS KOKOROOF HITAM | B910: 103555 | E910: 1 | F910: Pengurangan
A911: LIS 07 A BESAR / 4 M | B911: 101488 | E911: 240 | F911: Pengurangan | G911: 30780
A912: C75-75 6M ARRU TRUSS | B912: 101016 | E912: 250 | F912: Pengurangan | G912: 64000
A913: SPANDECK PASIR HITAM 0.30 x 5M KCNA | B913: 103505 | E913: 100 | F913: Pengurangan | G913: 322175
A914: SPANDECK PASIR HITAM 0.30 x 6M KCNA | B914: 103504 | E914: 200 | F914: Pengurangan | G914: 386610
A915: LIS WPC TW 917 / 3 M | B915: 103493 | E915: 7 | F915: Penambahan | G915: 26500
A916: MARMER 120*240*0,3 CM GWB 016 HYI | B916: 103439 | E916: 2 | F916: Penambahan | G916: 260000
A917: NOK C PUTRI SAYAP BIRU | B917: 103513 | E917: 20 | F917: Penambahan | G917: 12000

Sheet Template (2)
A1: Nama Barang | B1: Kode | C1: Unit | D1: Kuantitas | E1: Biaya Satuan | F1: Gudang | G1: Tipe Penyesuaian | H1: Nama Dept Barang | I1: No Proyek Barang
A2: ATAP 2 SSN BAMBU COKLAT GGROOF (RUSAK) | B2: 102097 | C2: LEMBAR | D2: =VLOOKUP(B2,'HASIL REKAP OPNAME 2'!$B$2:$E$9094,4,0) -> 16 | E2: 0 | F2: GUDANG PALANGKARAYA | G2: Pengurangan
A3: ATAP 2 SSN 0.25 HITAM MATTE | B3: 102042 | C3: LEMBAR | D3: =VLOOKUP(B3,'HASIL REKAP OPNAME 2'!$B$2:$E$9094,4,0) -> 0 | E3: 0 | F3: GUDANG PALANGKARAYA | G3: Penambahan
A4: ATAP 2 SSN 0.30 HITAM MATTE | B4: 102043 | C4: LEMBAR | D4: =VLOOKUP(B4,'HASIL REKAP OPNAME 2'!$B$2:$E$9094,4,0) -> 50 | E4: 0 | F4: GUDANG PALANGKARAYA | G4: Pengurangan
A5: ATAP 2 SSN COKLAT ARRU ROOF | B5: 100975 | C5: LEMBAR | D5: =VLOOKUP(B5,'HASIL REKAP OPNAME 2'!$B$2:$E$9094,4,0) -> 90 | E5: 0 | F5: GUDANG PALANGKARAYA | G5: Pengurangan
A6: ATAP 2 SSN COKLAT ARRU ROOF (RUSAK) | B6: 102196 | C6: LEMBAR | D6: =VLOOKUP(B6,'HASIL REKAP OPNAME 2'!$B$2:$E$9094,4,0) -> 6 | E6: 0 | F6: GUDANG PALANGKARAYA | G6: Pengurangan
A7: ATAP 2 SSN COKLAT DYNASTY | B7: 100977 | C7: LEMBAR | D7: =VLOOKUP(B7,'HASIL REKAP OPNAME 2'!$B$2:$E$9094,4,0) -> 0 | E7: 0 | F7: GUDANG PALANGKARAYA | G7: Penambahan
A8: ATAP 2 SSN COKLAT DYNASTY (RUSAK) | B8: 102198 | C8: LEMBAR | D8: =VLOOKUP(B8,'HASIL REKAP OPNAME 2'!$B$2:$E$9094,4,0) -> 2 | E8: 0 | F8: GUDANG PALANGKARAYA | G8: Pengurangan
A9: ATAP 2 SSN COKLAT MAHKOTA | B9: 100979 | C9: LEMBAR | D9: =VLOOKUP(B9,'HASIL REKAP OPNAME 2'!$B$2:$E$9094,4,0) -> 6 | E9: =VLOOKUP(B9,'Penyesuaian Persediaan - ARU'!$B$2:$G$813,6,0) -> 20500 | F9: GUDANG PALANGKARAYA | G9: Penambahan
A10: ATAP 2 SSN COKLAT MAHKOTA (RUSAK) | B10: 102200 | C10: LEMBAR | D10: =VLOOKUP(B10,'HASIL REKAP OPNAME 2'!$B$2:$E$9094,4,0) -> 3 | E10: 0 | F10: GUDANG PALANGKARAYA | G10: Pengurangan
A11: ATAP 2 SSN MAROON GGROOF | B11: 100983 | C11: LEMBAR | D11: =VLOOKUP(B11,'HASIL REKAP OPNAME 2'!$B$2:$E$9094,4,0) -> 3 | E11: =VLOOKUP(B11,'Penyesuaian Persediaan - ARU'!$B$2:$G$813,6,0) -> 20000 | F11: GUDANG PALANGKARAYA | G11: Penambahan
A12: ATAP 2 SSN MAROON GGROOF (RUSAK) | B12: 102204 | C12: LEMBAR | D12: =VLOOKUP(B12,'HASIL REKAP OPNAME 2'!$B$2:$E$9094,4,0) -> 2 | E12: 0 | F12: GUDANG PALANGKARAYA | G12: Pengurangan
A13: ATAP 2 SSN MERAH MAHKOTA | B13: 100984 | C13: LEMBAR | D13: =VLOOKUP(B13,'HASIL REKAP OPNAME 2'!$B$2:$E$9094,4,0) -> 5 | E13: =VLOOKUP(B13,'Penyesuaian Persediaan - ARU'!$B$2:$G$813,6,0) -> 99500 | F13: GUDANG PALANGKARAYA | G13: Penambahan
A14: ATAP 2 SSN MERAH MAHKOTA (RUSAK) | B14: 102205 | C14: LEMBAR | D14: =VLOOKUP(B14,'HASIL REKAP OPNAME 2'!$B$2:$E$9094,4,0) -> 2 | E14: 0 | F14: GUDANG PALANGKARAYA | G14: Pengurangan
A15: ATAP 2 SSN PASIR KOKOROOF | B15: 100985 | C15: LEMBAR | D15: =VLOOKUP(B15,'HASIL REKAP OPNAME 2'!$B$2:$E$9094,4,0) -> 1 | E15: 0 | F15: GUDANG PALANGKARAYA | G15: Pengurangan
A16: ATAP 2 SSN SAKURA ELANG TRENDY HITAM 2X4 | B16: 103484 | C16: LEMBAR | D16: =VLOOKUP(B16,'HASIL REKAP OPNAME 2'!$B$2:$E$9094,4,0) -> 1 | E16: 0 | F16: GUDANG PALANGKARAYA | G16: Pengurangan
A17: ATAP 2 SUSUN COKLAT FALCON | B17: 100989 | C17: LEMBAR | D17: =VLOOKUP(B17,'HASIL REKAP OPNAME 2'!$B$2:$E$9094,4,0) -> 40 | E17: 0 | F17: GUDANG PALANGKARAYA | G17: Pengurangan
A18: ATAP 2 SUSUN COKLAT FALCON (RUSAK) | B18: 102210 | C18: LEMBAR | D18: =VLOOKUP(B18,'HASIL REKAP OPNAME 2'!$B$2:$E$9094,4,0) -> 1 | E18: 0 | F18: GUDANG PALANGKARAYA | G18: Pengurangan
A19: ATAP MINIMALIS 2x2 PASIR HITAM | B19: 103310 | C19: LEMBAR | D19: =VLOOKUP(B19,'HASIL REKAP OPNAME 2'!$B$2:$E$9094,4,0) -> 10 | E19: 0 | F19: GUDANG PALANGKARAYA | G19: Pengurangan
A20: ATAP MINIMALIS PASIR HITAM METALINDO (RUSAK) | B20: 102219 | C20: LEMBAR | D20: =VLOOKUP(B20,'HASIL REKAP OPNAME 2'!$B$2:$E$9094,4,0) -> 1 | E20: 0 | F20: GUDANG PALANGKARAYA | G20: Pengurangan
A21: BAUT 10 X 16 PATTA | B21: 100999 | C21: KOTAK | D21: =VLOOKUP(B21,'HASIL REKAP OPNAME 2'!$B$2:$E$9094,4,0) -> 1 | E21: 0 | F21: GUDANG PALANGKARAYA | G21: Pengurangan
A22: BAUT ATAP 12 X 45 SUPERDIL | B22: 101003 | C22: KOTAK | D22: =VLOOKUP(B22,'HASIL REKAP OPNAME 2'!$B$2:$E$9094,4,0) -> 25 | E22: =VLOOKUP(B22,'Penyesuaian Persediaan - ARU'!$B$2:$G$813,6,0) -> 96000 | F22: GUDANG PALANGKARAYA | G22: Penambahan
A23: BAUT ATAP 12 X 50 SUPERDRILL | B23: 101004 | C23: KOTAK | D23: =VLOOKUP(B23,'HASIL REKAP OPNAME 2'!$B$2:$E$9094,4,0) -> 39 | E23: =VLOOKUP(B23,'Penyesuaian Persediaan - ARU'!$B$2:$G$813,6,0) -> 40000 | F23: GUDANG PALANGKARAYA | G23: Penambahan
A24: BAUT TASSO 10 X 16 LUMBA LUMBA | B24: 100998 | C24: KOTAK | D24: =VLOOKUP(B24,'HASIL REKAP OPNAME 2'!$B$2:$E$9094,4,0) -> 38 | E24: 0 | F24: GUDANG PALANGKARAYA | G24: Pengurangan
A25: BAUT TASSO 10 X 16 LUMBA LUMBA (800 pcs) | B25: 103456 | C25: KOTAK | D25: =VLOOKUP(B25,'HASIL REKAP OPNAME 2'!$B$2:$E$9094,4,0) -> 6 | E25: 0 | F25: GUDANG PALANGKARAYA | G25: Pengurangan
A26: BAUT TASSO 10 X 16 ONE FIX (1000 pcs) | B26: 103511 | C26: KOTAK | D26: =VLOOKUP(B26,'HASIL REKAP OPNAME 2'!$B$2:$E$9094,4,0) -> 10 | E26: 0 | F26: GUDANG PALANGKARAYA | G26: Pengurangan
A27: C75-65 6M ARRU TRUSS (RUSAK) | B27: 102242 | C27: BATANG | D27: =VLOOKUP(B27,'HASIL REKAP OPNAME 2'!$B$2:$E$9094,4,0) -> 1 | E27: 0 | F27: GUDANG PALANGKARAYA | G27: Pengurangan
A28: C75-65i 6 M ARRU (RUSAK) | B28: 102246 | C28: BATANG | D28: =VLOOKUP(B28,'HASIL REKAP OPNAME 2'!$B$2:$E$9094,4,0) -> 1 | E28: 0 | F28: GUDANG PALANGKARAYA | G28: Pengurangan
A29: C75-75 ARU TRUSS | B29: 103382 | C29: BATANG | D29: =VLOOKUP(B29,'HASIL REKAP OPNAME 2'!$B$2:$E$9094,4,0) -> 35 | E29: 0 | F29: GUDANG PALANGKARAYA | G29: Pengurangan
A30: C75-75 ECO ARU TRUSS | B30: 103383 | C30: BATANG | D30: =VLOOKUP(B30,'HASIL REKAP OPNAME 2'!$B$2:$E$9094,4,0) -> 60 | E30: 0 | F30: GUDANG PALANGKARAYA | G30: Pengurangan
A31: DAK 54 / 4M | B31: 101031 | C31: LEMBAR | D31: =VLOOKUP(B31,'HASIL REKAP OPNAME 2'!$B$2:$E$9094,4,0) -> 0 | E31: 0 | F31: GUDANG PALANGKARAYA | G31: Penambahan
A32: DAK 54 / 4M (RUSAK) | B32: 102269 | C32: LEMBAR | D32: =VLOOKUP(B32,'HASIL REKAP OPNAME 2'!$B$2:$E$9094,4,0) -> 4 | E32: 0 | F32: GUDANG PALANGKARAYA | G32: Pengurangan
A33: DYNABOLT 10 X 50 MARIO | B33: 101035 | C33: PCS | D33: =VLOOKUP(B33,'HASIL REKAP OPNAME 2'!$B$2:$E$9094,4,0) -> 146 | E33: 0 | F33: GUDANG PALANGKARAYA | G33: Pengurangan
A34: DYNABOLT 10 X 65 MARIO | B34: 101036 | C34: PCS | D34: =VLOOKUP(B34,'HASIL REKAP OPNAME 2'!$B$2:$E$9094,4,0) -> 452 | E34: 0 | F34: GUDANG PALANGKARAYA | G34: Pengurangan
A35: ELG 01 / 4 M | B35: 101038 | C35: LEMBAR | D35: =VLOOKUP(B35,'HASIL REKAP OPNAME 2'!$B$2:$E$9094,4,0) -> 8 | E35: =VLOOKUP(B35,'Penyesuaian Persediaan - ARU'!$B$2:$G$813,6,0) -> 36800 | F35: GUDANG PALANGKARAYA | G35: Penambahan
A36: ELG 01 / 4 M (RUSAK) | B36: 102276 | C36: LEMBAR | D36: =VLOOKUP(B36,'HASIL REKAP OPNAME 2'!$B$2:$E$9094,4,0) -> 11 | E36: 0 | F36: GUDANG PALANGKARAYA | G36: Pengurangan
A37: ELG 010 / 4 M | B37: 101039 | C37: LEMBAR | D37: =VLOOKUP(B37,'HASIL REKAP OPNAME 2'!$B$2:$E$9094,4,0) -> 197 | E37: =VLOOKUP(B37,'Penyesuaian Persediaan - ARU'!$B$2:$G$813,6,0) -> 36800 | F37: GUDANG PALANGKARAYA | G37: Penambahan
A38: ELG 010 / 4 M (RUSAK) | B38: 102277 | C38: LEMBAR | D38: =VLOOKUP(B38,'HASIL REKAP OPNAME 2'!$B$2:$E$9094,4,0) -> 10 | E38: 0 | F38: GUDANG PALANGKARAYA | G38: Pengurangan
A39: ELG 011 G / 4 M | B39: 101040 | C39: LEMBAR | D39: =VLOOKUP(B39,'HASIL REKAP OPNAME 2'!$B$2:$E$9094,4,0) -> 10 | E39: 0 | F39: GUDANG PALANGKARAYA | G39: Pengurangan
A40: ELG 014 / 4 M | B40: 101043 | C40: LEMBAR | D40: =VLOOKUP(B40,'HASIL REKAP OPNAME 2'!$B$2:$E$9094,4,0) -> 0 | E40: 0 | F40: GUDANG PALANGKARAYA | G40: Penambahan
...

Sheet Penyesuaian Persediaan - ARU
B1: Kode Barang | C1: Nama Barang | D1: Kts. | F1: Total Biaya | G1: HARGA BELI
B2: 102097 | C2: ATAP 2 SSN BAMBU COKLAT GGROOF (RUSAK) | D2: 16 | E2: Pengurangan | F2: 328000 | G2: =F2/D2 -> 20500
B3: 102043 | C3: ATAP 2 SSN 0.30 HITAM MATTE | D3: 50 | E3: Pengurangan | F3: 1650000 | G3: =F3/D3 -> 33000
B4: 100975 | C4: ATAP 2 SSN COKLAT ARRU ROOF | D4: 90 | E4: Pengurangan | F4: 1755000 | G4: =F4/D4 -> 19500
B5: 102196 | C5: ATAP 2 SSN COKLAT ARRU ROOF (RUSAK) | D5: 6 | E5: Pengurangan | F5: 117000 | G5: =F5/D5 -> 19500
B6: 102198 | C6: ATAP 2 SSN COKLAT DYNASTY (RUSAK) | D6: 2 | E6: Pengurangan | F6: 57600 | G6: =F6/D6 -> 28800
B7: 100979 | C7: ATAP 2 SSN COKLAT MAHKOTA | D7: 6 | E7: Penambahan | F7: 123000 | G7: =F7/D7 -> 20500
B8: 102200 | C8: ATAP 2 SSN COKLAT MAHKOTA (RUSAK) | D8: 3 | E8: Pengurangan | F8: 83687.143 | G8: =F8/D8 -> 27895.714
B9: 100983 | C9: ATAP 2 SSN MAROON GGROOF | D9: 3 | E9: Penambahan | F9: 60000 | G9: =F9/D9 -> 20000
B10: 102204 | C10: ATAP 2 SSN MAROON GGROOF (RUSAK) | D10: 2 | E10: Pengurangan | F10: 40000 | G10: =F10/D10 -> 20000
B11: 100984 | C11: ATAP 2 SSN MERAH MAHKOTA | D11: 5 | E11: Penambahan | F11: 497500 | G11: =F11/D11 -> 99500
B12: 102205 | C12: ATAP 2 SSN MERAH MAHKOTA (RUSAK) | D12: 2 | E12: Pengurangan | F12: 53827.755 | G12: =F12/D12 -> 26913.878
B13: 100985 | C13: ATAP 2 SSN PASIR KOKOROOF | D13: 1 | E13: Pengurangan | F13: 37500 | G13: =F13/D13 -> 37500
... B506: 102045 | C506: MARMER 120*240*0,3 CM GWB | D506: 1 | E506: Pengurangan | F506: 282010.99 | G506: =F506/D506 -> 282010.99
C507: 017 HYI | G507: =F507/D507 -> #DIV/0!
B508: 102012 | C508: MARMER 120*240*0,3 CM GWB 018 HYI | D508: 1 | E508: Pengurangan | F508: 281677.8 | G508: =F508/D508 -> 281677.8
B509: 102036 | C509: MARMER 120*240*0,3 CM GWB 019 HYI | D509: 1 | E509: Pengurangan | F509: 280031.1 | G509: =F509/D509 -> 280031.1
B510: 102175 | C510: MARMER 120*240*0,3 CM GWB 019-1 HYI | D510: 3 | E510: Penambahan | F510: 840000 | G510: =F510/D510 -> 280000
B511: 102018 | C511: MARMER 120*240*0,3 CM GWB 021 HYI | D511: 1 | E511: Pengurangan | F511: 266900.96 | G511: =F511/D511 -> 266900.96
B512: 102176 | C512: MARMER 120*240*0,3 CM GWB 07 HYI | D512: 2 | E512: Penambahan | F512: 540000 | G512: =F512/D512 -> 270000
B513: 101950 | C513: MATA GERINDA POTONG AI088 4 STEEL | D513: 5 | E513: Pengurangan | F513: 13000 | G513: =F513/D513 -> 2600
B514: 101567 | C514: MICRODECK BIRU 170CM SIMAPAN | D514: 20 | E514: Pengurangan | F514: 690000 | G514: =F514/D514 -> 34500
B515: 102854 | C515: MICRODECK BIRU 170CM SIMAPAN (RUSAK) | D515: 1 | E515: Pengurangan | F515: 34500 | G515: =F515/D515 -> 34500
B516: 102864 | C516: NOK JASS MAROON TATA (RUSAK) | D516: 10 | E516: Pengurangan | F516: 148000 | G516: =F516/D516 -> 14800
B517: 101576 | C517: NOK PASIR KOKOROFF | D517: 18 | E517: Pengurangan | F517: 468000 | G517: =F517/D517 -> 26000
B518: 101577 | C518: NOK PUTRI COKLAT IJ | D518: 14 | E518: Pengurangan | F518: 260400 | G518: =F518/D518 -> 18600
B519: 101996 | C519: NOK V PASIR HITAM 0.25 L 30 P 3M KCNA | D519: 1 | E519: Pengurangan | F519: 63014.851 | G519: =F519/D519 -> 63014.851
... B813: 103411 | C813: HOLLO 2X4 TALI HITAM | D813: 169 | E813: Penambahan | F813: 1199900 | G813: =F813/D813 -> 7100
G814: =F814/D814 -> #DIV/0!
G815: =F815/D815 -> #DIV/0!
G816: =F816/D816 -> #DIV/0!
G817: =F817/D817 -> #DIV/0!
G818: =F818/D818 -> #DIV/0!
G819: =F819/D819 -> #DIV/0!

Sheet OPANAME 2 PKY
A1: Nama Barang | B1: Kode | C1: SATUAN | D1: Unit | E1: SEBELUM SO | F1: SESUDAH SO KERTAS 1 | G1: SESUDAH SO KERTAS 2 | H1: HASIL | I1: RIJEK | K1: KETERANGAN | L1: HARGA BELI | M1: TOTAL
A2: ATAP 2 SSN BAMBU COKLAT GGROOF (RUSAK) | B2: #REF! | C2: =IFERROR(INDEX(#REF!,MATCH(B2,'Barang & Jasa'!#REF!,0)),0) -> 0 | D2: LEMBAR | E2: 16 | F2: #REF! | G2: #REF! | H2: =G2+F2-E2 -> #VALUE! | I2: #REF! | L2: #REF! | M2: =L2*H2 -> #VALUE!
A3: ATAP 2 SSN 0.25 HITAM MATTE | B3: #REF! | D3: LEMBAR | E3: 50 | F3: #REF! | G3: #REF! | H3: =G3+F3-E3 -> #VALUE! | I3: #REF! | L3: #REF! | M3: =L3*H3 -> #VALUE!
A4: ATAP 2 SSN 0.30 HITAM MATTE | B4: 102043 | D4: LEMBAR | E4: 50 | F4: 0 | G4: 0 | H4: =G4+F4-E4 -> -50 | I4: 0 | L4: 34500 | M4: =L4*H4 -> -1725000
A5: ATAP 2 SSN COKLAT ARRU ROOF | B5: #REF! | D5: LEMBAR | E5: 90 | F5: #REF! | G5: #REF! | H5: =G5+F5-E5 -> #VALUE! | I5: #REF! | L5: #REF! | M5: =L5*H5 -> #VALUE!
A6: ATAP 2 SSN COKLAT ARRU ROOF (RUSAK) | B6: #REF! | D6: LEMBAR | E6: 6 | F6: #REF! | G6: #REF! | H6: =G6+F6-E6 -> #VALUE! | I6: #REF! | L6: #REF! | M6: =L6*H6 -> #VALUE!
A7: ATAP 2 SSN COKLAT DYNASTY | B7: #REF! | D7: LEMBAR | E7: 100 | F7: #REF! | G7: #REF! | H7: =G7+F7-E7 -> #VALUE! | I7: #REF! | L7: #REF! | M7: =L7*H7 -> #VALUE!
A8: ATAP 2 SSN COKLAT DYNASTY (RUSAK) | B8: #REF! | D8: LEMBAR | E8: 2 | F8: #REF! | G8: #REF! | H8: =G8+F8-E8 -> #VALUE! | I8: #REF! | L8: #REF! | M8: =L8*H8 -> #VALUE!
A9: ATAP 2 SSN COKLAT MAHKOTA | B9: #REF! | D9: LEMBAR | E9: 15 | F9: #REF! | G9: #REF! | H9: =G9+F9-E9 -> #VALUE! | I9: #REF! | L9: #REF! | M9: =L9*H9 -> #VALUE!
A10: ATAP 2 SSN COKLAT MAHKOTA (RUSAK) | B10: #REF! | D10: LEMBAR | E10: 3 | F10: #REF! | G10: #REF! | H10: =G10+F10-E10 -> #VALUE! | I10: #REF! | L10: #REF! | M10: =L10*H10 -> #VALUE!
A11: ATAP 2 SSN MAROON GGROOF | B11: #REF! | D11: LEMBAR | E11: 7 | F11: #REF! | G11: #REF! | H11: =G11+F11-E11 -> #VALUE! | I11: #REF! | L11: #REF! | M11: =L11*H11 -> #VALUE!
A12: ATAP 2 SSN MAROON GGROOF (RUSAK) | B12: #REF! | D12: LEMBAR | E12: 2 | F12: #REF! | G12: #REF! | H12: =G12+F12-E12 -> #VALUE! | I12: #REF! | L12: #REF! | M12: =L12*H12 -> #VALUE!
A13: ATAP 2 SSN MERAH MAHKOTA | B13: #REF! | D13: LEMBAR | E13: 16 | F13: #REF! | G13: #REF! | H13: =G13+F13-E13 -> #VALUE! | I13: #REF! | L13: #REF! | M13: =L13*H13 -> #VALUE!
A14: ATAP 2 SSN MERAH MAHKOTA (RUSAK) | B14: #REF! | D14: LEMBAR | E14: 2 | F14: #REF! | G14: #REF! | H14: =G14+F14-E14 -> #VALUE! | I14: #REF! | L14: #REF! | M14: =L14*H14 -> #VALUE!
A15: ATAP 2 SSN PASIR KOKOROOF | B15: #REF! | D15: LEMBAR | E15: 61 | F15: #REF! | G15: #REF! | H15: =G15+F15-E15 -> #VALUE! | I15: #REF! | L15: #REF! | M15: =L15*H15 -> #VALUE!
A16: ATAP 2 SSN SAKURA ELANG TRENDY HITAM 2X4 | B16: #REF! | D16: LEMBAR | E16: 1 | F16: #REF! | G16: #REF! | H16: =G16+F16-E16 -> #VALUE! | I16: #REF! | L16: #REF! | M16: =L16*H16 -> #VALUE!
... A20: ATAP MINIMALIS PASIR HITAM METALINDO (RUSAK) | B20: #REF! | D20: LEMBAR | E20: 1 | F20: #REF! | G20: #REF! | H20: =G20+F20-E20 -> #VALUE! | I20: #REF! | L20: #REF! | M20: =L20*H20 -> #VALUE!
A21: BAUT 10 X 16 PATTA | B21: #REF! | E21: 5 | F21: #REF! | G21: #REF! | H21: =G21+F21-E21 -> #VALUE! | I21: #REF! | L21: #REF! | M21: =L21*H21 -> #VALUE!
A22: BAUT ATAP 12 X 45 SUPERDIL | B22: #REF! | E22: 59 | F22: #REF! | G22: #REF! | H22: =G22+F22-E22 -> #VALUE! | I22: #REF! | L22: #REF! | M22: =L22*H22 -> #VALUE!
A23: BAUT ATAP 12 X 50 SUPERDRILL | B23: #REF! | E23: 52 | F23: #REF! | G23: #REF! | H23: =G23+F23-E23 -> #VALUE! | I23: #REF! | L23: #REF! | M23: =L23*H23 -> #VALUE!
A24: BAUT TASSO 10 X 16 LUMBA LUMBA | B24: #REF! | E24: 38 | F24: #REF! | G24: #REF! | H24: =G24+F24-E24 -> #VALUE! | I24: #REF! | L24: #REF! | M24: =L24*H24 -> #VALUE!
A25: BAUT TASSO 10 X 16 LUMBA LUMBA (800 pcs) | B25: #REF! | E25: 16 | F25: #REF! | G25: #REF! | H25: =G25+F25-E25 -> #VALUE! | I25: #REF! | L25: #REF! | M25: =L25*H25 -> #VALUE!
A26: BAUT TASSO 10 X 16 ONE FIX (1000 pcs) | B26: #REF! | E26: 30 | F26: #REF! | G26: #REF! | H26: =G26+F26-E26 -> #VALUE! | I26: #REF! | L26: #REF! | M26: =L26*H26 -> #VALUE!
A27: C75-65 6M ARRU TRUSS (RUSAK) | B27: 102242 | E27: 1 | F27: 0 | G27: 0 | H27: =G27+F27-E27 -> -1 | I27: 0 | L27: 56465 | M27: =L27*H27 -> -56465
A28: C75-65i 6 M ARRU (RUSAK) | B28: 102246 | E28: 1 | F28: 0 | G28: 0 | H28: =G28+F28-E28 -> -1 | I28: 0 | L28: 56465 | M28: =L28*H28 -> -56465
A29: C75-75 ARU TRUSS | B29: #REF! | E29: 35 | F29: #REF! | G29: #REF! | H29: =G29+F29-E29 -> #VALUE! | I29: #REF! | L29: #REF! | M29: =L29*H29 -> #VALUE!
A30: C75-75 ECO ARU TRUSS | B30: #REF! | E30: 312 | F30: #REF! | G30: #REF! | H30: =G30+F30-E30 -> #VALUE! | I30: #REF! | L30: #REF! | M30: =L30*H30 -> #VALUE!
A31: DAK 54 / 4M | B31: #REF! | E31: 0 | F31: #REF! | G31: #REF! | H31: =G31+F31-E31 -> #VALUE! | I31: #REF! | L31: #REF! | M31: =L31*H31 -> #VALUE!
A32: DAK 54 / 4M (RUSAK) | B32: #REF! | E32: 4 | F32: #REF! | G32: #REF! | H32: =G32+F32-E32 -> #VALUE! | I32: #REF! | L32: #REF! | M32: =L32*H32 -> #VALUE!
A33: DYNABOLT 10 X 50 MARIO | B33: #REF! | E33: 146 | F33: #REF! | G33: #REF! | H33: =G33+F33-E33 -> #VALUE! | I33: #REF! | L33: #REF! | M33: =L33*H33 -> #VALUE!
A34: DYNABOLT 10 X 65 MARIO | B34: #REF! | E34: 452 | F34: #REF! | G34: #REF! | H34: =G34+F34-E34 -> #VALUE! | I34: #REF! | L34: #REF! | M34: =L34*H34 -> #VALUE!
A35: ELG 01 / 4 M | B35: #REF! | E35: 0 | F35: #REF! | G35: #REF! | H35: =G35+F35-E35 -> #VALUE! | I35: #REF! | L35: #REF! | M35: =L35*H35 -> #VALUE!
A36: ELG 01 / 4 M (RUSAK) | B36: #REF! | E36: 11 | F36: #REF! | G36: #REF! | H36: =G36+F36-E36 -> #VALUE! | I36: #REF! | L36: #REF! | M36: =L36*H36 -> #VALUE!
A37: ELG 010 / 4 M | B37: #REF! | E37: 100 | F37: #REF! | G37: #REF! | H37: =G37+F37-E37 -> #VALUE! | I37: #REF! | L37: #REF! | M37: =L37*H37 -> #VALUE!
A38: ELG 010 / 4 M (RUSAK) | B38: #REF! | E38: 10 | F38: #REF! | G38: #REF! | H38: =G38+F38-E38 -> #VALUE! | I38: #REF! | L38: #REF! | M38: =L38*H38 -> #VALUE!
A39: ELG 011 G / 4 M | B39: #REF! | E39: 10 | F39: #REF! | G39: #REF! | H39: =G39+F39-E39 -> #VALUE! | I39: #REF! | L39: #REF! | M39: =L39*H39 -> #VALUE!
A40: ELG 014 / 4 M | B40: #REF! | E40: 16 | F40: #REF! | G40: #REF! | H40: =G40+F40-E40 -> #VALUE! | I40: #REF! | L40: #REF! | M40: =L40*H40 -> #VALUE!
... A108: ELG 08 / 4 M (RUSAK) | B108: #REF! | E108: 2 | F108: #REF! | G108: #REF! | H108: =G108+F108-E108 -> #VALUE! | I108: #REF! | L108: #REF! | M108: =L108*H108 -> #VALUE!
A109: ELG 09 / 3 M | B109: #REF! | E109: 0 | F109: #REF! | G109: #REF! | H109: =G109+F109-E109 -> #VALUE! | I109: #REF! | L109: 31000 | M109: =L109*H109 -> #VALUE!
A110: ELG 09 / 3 M (RUSAK) | B110: #REF! | E110: 11 | F110: #REF! | G110: #REF! | H110: =G110+F110-E110 -> #VALUE! | I110: #REF! | L110: #REF! | M110: =L110*H110 -> #VALUE!
...

Sheet PEMINDAHAN BARANG
B1: Kode | C1: Nama Barang | D1: Qty | E1: SATUAN
B2: 101241 | C2: HM 38 / 4 M | D2: 80 | E2: LEMBAR | F2: =VLOOKUP(B2,'Template FIX'!$B$2:$C$820,2,0) -> LEMBAR | G2: =VLOOKUP(B2,'HASIL REKAP OPNAME 2'!B$2:C$917,2,0) -> LEMBAR
B3: 101178 | C3: HM 07 / 4 M | D3: 160 | E3: LEMBAR | F3: =VLOOKUP(B3,'Template FIX'!$B$2:$C$820,2,0) -> LEMBAR | G3: =VLOOKUP(B3,'HASIL REKAP OPNAME 2'!B$2:C$917,2,0) -> LEMBAR
B4: 101327 | C4: JANUR V - A 3CM*4M | D4: 231 | E4: BATANG | F4: =VLOOKUP(B4,'Template FIX'!$B$2:$C$820,2,0) -> BATANG | G4: =VLOOKUP(B4,'HASIL REKAP OPNAME 2'!B$2:C$917,2,0) -> BATANG
B5: 101201 | C5: HM 18 / 4 M | D5: 80 | E5: LEMBAR | F5: =VLOOKUP(B5,'Template FIX'!$B$2:$C$820,2,0) -> LEMBAR | G5: =VLOOKUP(B5,'HASIL REKAP OPNAME 2'!B$2:C$917,2,0) -> LEMBAR
B6: 101141 | C6: EWP KPK 03 / 3M | D6: 200 | E6: LEMBAR | F6: =VLOOKUP(B6,'Template FIX'!$B$2:$C$820,2,0) -> LEMBAR | G6: =VLOOKUP(B6,'HASIL REKAP OPNAME 2'!B$2:C$917,2,0) -> LEMBAR
B7: 102017 | C7: MARMER 120*240*0,3 CM GWB 020 HYI | D7: 2 | E7: LEMBAR | F7: =VLOOKUP(B7,'Template FIX'!$B$2:$C$820,2,0) -> #N/A | G7: =VLOOKUP(B7,'HASIL REKAP OPNAME 2'!B$2:C$917,2,0) -> LEMBAR
B8: 102012 | C8: MARMER 120*240*0,3 CM GWB 018 HYI | D8: 2 | E8: LEMBAR | F8: =VLOOKUP(B8,'Template FIX'!$B$2:$C$820,2,0) -> #N/A | G8: =VLOOKUP(B8,'HASIL REKAP OPNAME 2'!B$2:C$917,2,0) -> LEMBAR
B9: 103439 | C9: MARMER 120*240*0,3 CM GWB 016 HYI | D9: 2 | E9: LEMBAR | F9: =VLOOKUP(B9,'Template FIX'!$B$2:$C$820,2,0) -> #N/A | G9: =VLOOKUP(B9,'HASIL REKAP OPNAME 2'!B$2:C$917,2,0) -> 0
B10: 103440 | C10: MARMER 120*240*0,3 CM GWB 007 HYI | D10: 2 | E10: LEMBAR | F10: =VLOOKUP(B10,'Template FIX'!$B$2:$C$820,2,0) -> #N/A | G10: =VLOOKUP(B10,'HASIL REKAP OPNAME 2'!B$2:C$917,2,0) -> #N/A
B11: 102045 | C11: MARMER 120*240*0,3 CM GWB 017 HYI | D11: 2 | E11: LEMBAR | F11: =VLOOKUP(B11,'Template FIX'!$B$2:$C$820,2,0) -> LEMBAR | G11: =VLOOKUP(B11,'HASIL REKAP OPNAME 2'!B$2:C$917,2,0) -> LEMBAR
B12: 101281 | C12: JANUR 04 - A 4CM*4M | D12: 252 | E12: BATANG | F12: =VLOOKUP(B12,'Template FIX'!$B$2:$C$820,2,0) -> BATANG | G12: =VLOOKUP(B12,'HASIL REKAP OPNAME 2'!B$2:C$917,2,0) -> BATANG
B13: 102175 | C13: MARMER 120*240*0,3 CM GWB 019-1 HYI | D13: 3 | E13: LEMBAR | F13: =VLOOKUP(B13,'Template FIX'!$B$2:$C$820,2,0) -> #N/A | G13: =VLOOKUP(B13,'HASIL REKAP OPNAME 2'!B$2:C$917,2,0) -> LEMBAR
... B16: 103377 | C16: HOLLO 2X4 CAN (6725) | D16: 2000 | E16: BATANG | F16: =VLOOKUP(B16,'Template FIX'!$B$2:$C$820,2,0) -> BATANG | G16: =VLOOKUP(B16,'HASIL REKAP OPNAME 2'!B$2:C$917,2,0) -> BATANG

Sheet Rincian Penerimaan Barang
C1: Kode # | D1: Nama Barang | E1: Kuantitas | F1: Satuan | G1: Kode | H1: Nama Barang | I1: Kuantitas
C2: 101553 | D2: LIST PLANK 4M POLOS NUSAPLANK | E2: 8 | F2: BATANG | G2: 101553 | H2: =VLOOKUP(G2,$C$2:$D$744,2,0) -> LIST PLANK 4M POLOS NUSAPLANK | I2: 8
C3: 103555 | D3: ATAP 2 SSN 0,25 TANPA PASIR MINIMALIS KOKOROOF HITAM | E3: 155 | F3: LEMBAR | G3: 103555 | H3: =VLOOKUP(G3,$C$2:$D$744,2,0) -> ATAP 2 SSN 0,25 TANPA PASIR MINIMALIS KOKOROOF HITAM | I3: 155
C4: 101610 | D4: OR. 60 S4 SB | E4: 100 | F4: PCS | G4: 101610 | H4: =VLOOKUP(G4,$C$2:$D$744,2,0) -> OR. 60 S4 SB | I4: 100
C5: 101356 | D5: JV 017 / 4 M | E5: 300 | F5: LEMBAR | G5: 101356 | H5: =VLOOKUP(G5,$C$2:$D$744,2,0) -> JV 017 / 4 M | I5: 300
C6: 101357 | D6: JV 018 / 4 M | E6: 300 | F6: LEMBAR | G6: 101357 | H6: =VLOOKUP(G6,$C$2:$D$744,2,0) -> JV 018 / 4 M | I6: 300
C7: 101362 | D7: JV 023 / 4 M | E7: 756 | F7: LEMBAR | G7: 101362 | H7: =VLOOKUP(G7,$C$2:$D$744,2,0) -> JV 023 / 4 M | I7: 756
C8: 101414 | D8: JV 136 / 4 M | E8: 120 | F8: LEMBAR | G8: 101414 | H8: =VLOOKUP(G8,$C$2:$D$744,2,0) -> JV 136 / 4 M | I8: 120
C9: 101386 | D9: JV 045 / 4 M | E9: 120 | F9: LEMBAR | G9: 101386 | H9: =VLOOKUP(G9,$C$2:$D$744,2,0) -> JV 045 / 4 M | I9: 120
C10: 101401 | D10: JV 060 / 4 M | E10: 72 | F10: LEMBAR | G10: 101401 | H10: =VLOOKUP(G10,$C$2:$D$744,2,0) -> JV 060 / 4 M | I10: 72
C11: 101396 | D11: JV 055 / 4 M | E11: 120 | F11: LEMBAR | G11: 101396 | H11: =VLOOKUP(G11,$C$2:$D$744,2,0) -> JV 055 / 4 M | I11: 120
C12: 101384 | D12: JV 043 / 4 M | E12: 120 | F12: LEMBAR | G12: 101384 | H12: =VLOOKUP(G12,$C$2:$D$744,2,0) -> JV 043 / 4 M | I12: 120
C13: 101393 | D13: JV 052 / 4 M | E13: 120 | F13: LEMBAR | G13: 101393 | H13: =VLOOKUP(G13,$C$2:$D$744,2,0) -> JV 052 / 4 M | I13: 120
... C70: 101281 | D70: JANUR 04 - A 4CM*4M | E70: 252 | F70: BATANG | G70: 103377 | H70: =VLOOKUP(G70,$C$2:$D$744,2,0) -> HOLLO 2X4 CAN (6725) | I70: 2000
C71: 102175 | D71: MARMER 120*240*0,3 CM GWB 019-1 HYI | E71: 3 | F71: LEMBAR
C72: 101336 | D72: JANUR YTY04 4CM*3M | E72: 260 | F72: BATANG
C73: 103411 | D73: HOLLO 2X4 TALI HITAM | E73: 5000 | F73: BATANG
C74: 103377 | D74: HOLLO 2X4 CAN (6725) | E74: 2000 | F74: BATANG

Sheet Rincian Pesanan Penjualan
C1: Kode # | D1: Nama Barang | E1: Kuantitas | F1: @Harga | G1: Total Harga | H1: CEK | L1: Kode # | M1: Kuantitas | P1: CONSOLIDATE | Q1: Kuantitas
C2: 103555 | D2: ATAP 2 SSN 0,25 TANPA PASIR MINIMALIS KOKOROOF HITAM | E2: 154 | F2: 35000 | G2: 5390000 | H2: =VLOOKUP(C2,'REKAP OPNAME 2 '!$I$2:$J$9094,2,0) -> #N/A | L2: 103555 | M2: 154 | O2: 103555 | P2: =VLOOKUP(O2,$C$2:$D$3134,2,0) -> ATAP 2 SSN 0,25 TANPA PASIR MINIMALIS KOKOROOF HITAM | Q2: 154 | R2: =VLOOKUP(O2,'HASIL REKAP OPNAME 2'!$B$2:$C$909,2,0) -> #N/A
C3: 101003 | D3: BAUT ATAP 12 X 45 SUPERDIL | E3: 1 | F3: 130500 | G3: 130500 | H3: =VLOOKUP(C3,'REKAP OPNAME 2 '!$I$2:$J$9094,2,0) -> BAUT ATAP 12 X 45 SUPERDIL | L3: 101003 | M3: 1 | O3: 101003 | P3: =VLOOKUP(O3,$C$2:$D$3134,2,0) -> BAUT ATAP 12 X 45 SUPERDIL | Q3: 1 | R3: =VLOOKUP(O3,'HASIL REKAP OPNAME 2'!$B$2:$C$909,2,0) -> KOTAK
C4: 103456 | D4: BAUT TASSO 10 X 16 LUMBA LUMBA (800 pcs) | E4: 3 | F4: 126500 | G4: 379500 | H4: =VLOOKUP(C4,'REKAP OPNAME 2 '!$I$2:$J$9094,2,0) -> BAUT TASSO 10 X 16 LUMBA LUMBA (800 pcs) | L4: 103456 | M4: 3 | O4: 103456 | P4: =VLOOKUP(O4,$C$2:$D$3134,2,0) -> BAUT TASSO 10 X 16 LUMBA LUMBA (800 pcs) | Q4: 4 | R4: =VLOOKUP(O4,'HASIL REKAP OPNAME 2'!$B$2:$C$909,2,0) -> KOTAK
C5: 103456 | D5: BAUT TASSO 10 X 16 LUMBA LUMBA (800 pcs) | E5: 1 | F5: 126500 | G5: 126500 | H5: =VLOOKUP(C5,'REKAP OPNAME 2 '!$I$2:$J$9094,2,0) -> BAUT TASSO 10 X 16 LUMBA LUMBA (800 pcs) | L5: 103456 | M5: 1 | O5: 103383 | P5: =VLOOKUP(O5,$C$2:$D$3134,2,0) -> C75-75 ECO ARU TRUSS | Q5: 272 | R5: =VLOOKUP(O5,'HASIL REKAP OPNAME 2'!$B$2:$C$909,2,0) -> BATANG
C6: 103383 | D6: C75-75 ECO ARU TRUSS | E6: 8 | F6: 69000 | G6: 552000 | H6: =VLOOKUP(C6,'REKAP OPNAME 2 '!$I$2:$J$9094,2,0) -> C75-75 ECO ARU TRUSS | L6: 103383 | M6: 8 | O6: 101039 | P6: =VLOOKUP(O6,$C$2:$D$3134,2,0) -> ELG 010 / 4 M | Q6: 30 | R6: =VLOOKUP(O6,'HASIL REKAP OPNAME 2'!$B$2:$C$909,2,0) -> LEMBAR
C7: 103383 | D7: C75-75 ECO ARU TRUSS | E7: 2 | F7: 69000 | G7: 138000 | H7: =VLOOKUP(C7,'REKAP OPNAME 2 '!$I$2:$J$9094,2,0) -> C75-75 ECO ARU TRUSS | L7: 103383 | M7: 2 | O7: 101044 | P7: =VLOOKUP(O7,$C$2:$D$3134,2,0) -> ELG 015 / 4 M | Q7: 40 | R7: =VLOOKUP(O7,'HASIL REKAP OPNAME 2'!$B$2:$C$909,2,0) -> LEMBAR
C8: 103383 | D8: C75-75 ECO ARU TRUSS | E8: 30 | F8: 68000 | G8: 2040000 | H8: =VLOOKUP(C8,'REKAP OPNAME 2 '!$I$2:$J$9094,2,0) -> C75-75 ECO ARU TRUSS | L8: 103383 | M8: 30 | O8: 101050 | P8: =VLOOKUP(O8,$C$2:$D$3134,2,0) -> ELG 02 / 4 M | Q8: 16 | R8: =VLOOKUP(O8,'HASIL REKAP OPNAME 2'!$B$2:$C$909,2,0) -> LEMBAR
C9: 103383 | D9: C75-75 ECO ARU TRUSS | E9: 50 | F9: 68000 | G9: 3400000 | H9: =VLOOKUP(C9,'REKAP OPNAME 2 '!$I$2:$J$9094,2,0) -> C75-75 ECO ARU TRUSS | L9: 103383 | M9: 50 | O9: 101095 | P9: =VLOOKUP(O9,$C$2:$D$3134,2,0) -> ELG 11 FILM / 4M | Q9: 8 | R9: =VLOOKUP(O9,'HASIL REKAP OPNAME 2'!$B$2:$C$909,2,0) -> LEMBAR
C10: 103383 | D10: C75-75 ECO ARU TRUSS | E10: 182 | F10: 68000 | G10: 12376000 | H10: =VLOOKUP(C10,'REKAP OPNAME 2 '!$I$2:$J$9094,2,0) -> C75-75 ECO ARU TRUSS | L10: 103383 | M10: 182 | O10: 101099 | P10: =VLOOKUP(O10,$C$2:$D$3134,2,0) -> ELG 12 FILM / 4M | Q10: 92 | R10: =VLOOKUP(O10,'HASIL REKAP OPNAME 2'!$B$2:$C$909,2,0) -> LEMBAR
C11: 101039 | D11: ELG 010 / 4 M | E11: 30 | F11: 51500 | G11: 1530000 | H11: =VLOOKUP(C11,'REKAP OPNAME 2 '!$I$2:$J$9094,2,0) -> ELG 010 / 4 M | L11: 101039 | M11: 30 | O11: 101141 | P11: =VLOOKUP(O11,$C$2:$D$3134,2,0) -> EWP KPK 03 / 3M | Q11: 50 | R11: =VLOOKUP(O11,'HASIL REKAP OPNAME 2'!$B$2:$C$909,2,0) -> LEMBAR
C12: 101044 | D12: ELG 015 / 4 M | E12: 40 | F12: 60000 | G12: 2400000 | H12: =VLOOKUP(C12,'REKAP OPNAME 2 '!$I$2:$J$9094,2,0) -> ELG 015 / 4 M | L12: 101044 | M12: 40 | O12: 101147 | P12: =VLOOKUP(O12,$C$2:$D$3134,2,0) -> FITTING BTK - 002 | Q12: 4 | R12: =VLOOKUP(O12,'HASIL REKAP OPNAME 2'!$B$2:$C$909,2,0) -> PCS
C13: 101050 | D13: ELG 02 / 4 M | E13: 16 | F13: 53500 | G13: 856000 | H13: =VLOOKUP(C13,'REKAP OPNAME 2 '!$I$2:$J$9094,2,0) -> ELG 02 / 4 M | L13: 101050 | M13: 16 | O13: 101148 | P13: =VLOOKUP(O13,$C$2:$D$3134,2,0) -> FITTING BTK - 003 | Q13: 34 | R13: =VLOOKUP(O13,'HASIL REKAP OPNAME 2'!$B$2:$C$909,2,0) -> PCS
... C142: 101329 | D142: JANUR V - B 3CM*4M | E142: 7 | F142: 27500 | G142: 192500 | H142: =VLOOKUP(C142,'REKAP OPNAME 2 '!$I$2:$J$9094,2,0) -> JANUR V - B 3CM*4M | L142: 101329 | M142: 7 | O142: 103337 | P142: =VLOOKUP(O142,$C$2:$D$3134,2,0) -> WPC TW 916 / 3M | Q142: 41 | R142: =VLOOKUP(O142,'HASIL REKAP OPNAME 2'!$B$2:$C$909,2,0) -> LEMBAR
C143: 101330 | D143: JANUR V - B2 3CM*4M | E143: 70 | F143: 26500 | G143: 1855000 | H143: =VLOOKUP(C143,'REKAP OPNAME 2 '!$I$2:$J$9094,2,0) -> JANUR V - B2 3CM*4M | L143: 101330 | M143: 70
C144: 101336 | D144: JANUR YTY04 4CM*3M | E144: 94 | F144: 23500 | G144: 2209000 | H144: =VLOOKUP(C144,'REKAP OPNAME 2 '!$I$2:$J$9094,2,0) -> JANUR YTY04 4CM*3M | L144: 101336 | M144: 94
C145: 101336 | D145: JANUR YTY04 4CM*3M | E145: 130 | F145: 25500 | G145: 3315000 | H145: =VLOOKUP(C145,'REKAP OPNAME 2 '!$I$2:$J$9094,2,0) -> JANUR YTY04 4CM*3M | L145: 101336 | M145: 130
C146: 101336 | D146: JANUR YTY04 4CM*3M | E146: 34 | F146: 26500 | G146: 901000 | H146: =VLOOKUP(C146,'REKAP OPNAME 2 '!$I$2:$J$9094,2,0) -> JANUR YTY04 4CM*3M | L146: 101336 | M146: 34
C147: 102110 | D147: JANUR YTY06 6CM*3M | E147: 20 | F147: 40000 | G147: 800000 | H147: =VLOOKUP(C147,'REKAP OPNAME 2 '!$I$2:$J$9094,2,0) -> JANUR YTY06 6CM*3M | L147: 102110 | M147: 20
C148: 101341 | D148: JV 002 / 4 M | E148: 12 | F148: 78500 | G148: 942000 | H148: =VLOOKUP(C148,'REKAP OPNAME 2 '!$I$2:$J$9094,2,0) -> JV 002 / 4 M | L148: 101341 | M148: 12
C149: 101341 | D149: JV 002 / 4 M | E149: 8 | F149: 78500 | G149: 628000 | H149: =VLOOKUP(C149,'REKAP OPNAME 2 '!$I$2:$J$9094,2,0) -> JV 002 / 4 M | L149: 101341 | M149: 8
C150: 101351 | D150: JV 012 / 4 M | E150: 108 | F150: 78500 | G150: 8478000 | H150: =VLOOKUP(C150,'REKAP OPNAME 2 '!$I$2:$J$9094,2,0) -> JV 012 / 4 M | L150: 101351 | M150: 108
C151: 101356 | D151: JV 017 / 4 M | E151: 12 | F151: 75500 | G151: 876000 | H151: =VLOOKUP(C151,'REKAP OPNAME 2 '!$I$2:$J$9094,2,0) -> JV 017 / 4 M | L151: 101356 | M151: 12
C152: 101357 | D152: JV 018 / 4 M | E152: 24 | F152: 78500 | G152: 1884000 | H152: =VLOOKUP(C152,'REKAP OPNAME 2 '!$I$2:$J$9094,2,0) -> JV 018 / 4 M | L152: 101357 | M152: 24
C153: 101357 | D153: JV 018 / 4 M | E153: 7 | F153: 78500 | G153: 549500 | H153: =VLOOKUP(C153,'REKAP OPNAME 2 '!$I$2:$J$9094,2,0) -> JV 018 / 4 M | L153: 101357 | M153: 7
C154: 101357 | D154: JV 018 / 4 M | E154: 8 | F154: 78500 | G154: 628000 | H154: =VLOOKUP(C154,'REKAP OPNAME 2 '!$I$2:$J$9094,2,0) -> JV 018 / 4 M | L154: 101357 | M154: 8
... C313: 103337 | D313: WPC TW 916 / 3M | E313: 20 | F313: 70000 | G313: 1400000 | H313: =VLOOKUP(C313,'REKAP OPNAME 2 '!$I$2:$J$9094,2,0) -> WPC TW 916 / 3M | L313: 103337 | M313: 20

Sheet REKAP OPNAME 2 
A1: Nama Barang | B1: KODE BARANG | D1: QTY | E1: Penerimaan | F1: Penjualan | G1: HASIL | I1: KODE BARANG | J1: Nama Barang
A2: ATAP 2 SSN BAMBU COKLAT GGROOF (RUSAK) | B2: 102097 | D2: -16 | G2: =D2-E2+F2 -> -16 | I2: 102097 | J2: ATAP 2 SSN BAMBU COKLAT GGROOF (RUSAK)
A3: ATAP 2 SSN 0.25 HITAM MATTE | B3: 102042 | D3: 0 | G3: =D3-E3+F3 -> 0 | I3: 102042 | J3: ATAP 2 SSN 0.25 HITAM MATTE
A4: ATAP 2 SSN 0.30 HITAM MATTE | B4: 102043 | D4: -50 | G4: =D4-E4+F4 -> -50 | I4: 102043 | J4: ATAP 2 SSN 0.30 HITAM MATTE
A5: ATAP 2 SSN COKLAT ARRU ROOF | B5: 100975 | D5: -90 | G5: =D5-E5+F5 -> -90 | I5: 100975 | J5: ATAP 2 SSN COKLAT ARRU ROOF
A6: ATAP 2 SSN COKLAT ARRU ROOF (RUSAK) | B6: 102196 | D6: -6 | G6: =D6-E6+F6 -> -6 | I6: 102196 | J6: ATAP 2 SSN COKLAT ARRU ROOF (RUSAK)
A7: ATAP 2 SSN COKLAT DYNASTY | B7: 100977 | D7: 0 | G7: =D7-E7+F7 -> 0 | I7: 100977 | J7: ATAP 2 SSN COKLAT DYNASTY
A8: ATAP 2 SSN COKLAT DYNASTY (RUSAK) | B8: 102198 | D8: -2 | G8: =D8-E8+F8 -> -2 | I8: 102198 | J8: ATAP 2 SSN COKLAT DYNASTY (RUSAK)
A9: ATAP 2 SSN COKLAT MAHKOTA | B9: 100979 | D9: 6 | G9: =D9-E9+F9 -> 6 | I9: 100979 | J9: ATAP 2 SSN COKLAT MAHKOTA
A10: ATAP 2 SSN COKLAT MAHKOTA (RUSAK) | B10: 102200 | D10: -3 | G10: =D10-E10+F10 -> -3 | I10: 102200 | J10: ATAP 2 SSN COKLAT MAHKOTA (RUSAK)
A11: ATAP 2 SSN MAROON GGROOF | B11: 100983 | D11: 3 | G11: =D11-E11+F11 -> 3 | I11: 100983 | J11: ATAP 2 SSN MAROON GGROOF
A12: ATAP 2 SSN MAROON GGROOF (RUSAK) | B12: 102204 | D12: -2 | G12: =D12-E12+F12 -> -2 | I12: 102204 | J12: ATAP 2 SSN MAROON GGROOF (RUSAK)
A13: ATAP 2 SSN MERAH MAHKOTA | B13: 100984 | D13: 5 | G13: =D13-E13+F13 -> 5 | I13: 100984 | J13: ATAP 2 SSN MERAH MAHKOTA
... A21: BAUT 10 X 16 PATTA | B21: 100999 | D21: -1 | G21: =D21-E21+F21 -> -1 | I21: 100999 | J21: BAUT 10 X 16 PATTA
A22: BAUT ATAP 12 X 45 SUPERDIL | B22: 101003 | D22: 24 | F22: =VLOOKUP(B22,'Rincian Pesanan Penjualan'!$O$2:$Q$142,3,0) -> 1 | G22: =D22-E22+F22 -> 25 | I22: 101003 | J22: BAUT ATAP 12 X 45 SUPERDIL
A23: BAUT ATAP 12 X 50 SUPERDRILL | B23: 101004 | D23: 39 | G23: =D23-E23+F23 -> 39 | I23: 101004 | J23: BAUT ATAP 12 X 50 SUPERDRILL
A24: BAUT TASSO 10 X 16 LUMBA LUMBA | B24: 100998 | D24: -38 | G24: =D24-E24+F24 -> -38 | I24: 100998 | J24: BAUT TASSO 10 X 16 LUMBA LUMBA
A25: BAUT TASSO 10 X 16 LUMBA LUMBA (800 pcs) | B25: 103456 | D25: -10 | F25: =VLOOKUP(B25,'Rincian Pesanan Penjualan'!$O$2:$Q$142,3,0) -> 4 | G25: =D25-E25+F25 -> -6 | I25: 103456 | J25: BAUT TASSO 10 X 16 LUMBA LUMBA (800 pcs)
A26: BAUT TASSO 10 X 16 ONE FIX (1000 pcs) | B26: 103511 | D26: -10 | G26: =D26-E26+F26 -> -10 | I26: 103511 | J26: BAUT TASSO 10 X 16 ONE FIX (1000 pcs)
A27: C75-65 6M ARRU TRUSS (RUSAK) | B27: 102242 | D27: -1 | G27: =D27-E27+F27 -> -1 | I27: 102242 | J27: C75-65 6M ARRU TRUSS (RUSAK)
A28: C75-65i 6 M ARRU (RUSAK) | B28: 102246 | D28: -1 | G28: =D28-E28+F28 -> -1 | I28: 102246 | J28: C75-65i 6 M ARRU (RUSAK)
A29: C75-75 ARU TRUSS | B29: 103382 | D29: 129 | E29: =VLOOKUP(B29,'Rincian Penerimaan Barang'!$G$2:$I$70,3,0) -> 164 | G29: =D29-E29+F29 -> -35 | I29: 103382 | J29: C75-75 ARU TRUSS
A30: C75-75 ECO ARU TRUSS | B30: 103383 | D30: -212 | F30: =VLOOKUP(B30,'Rincian Pesanan Penjualan'!$O$2:$Q$142,3,0) -> 272 | G30: =D30-E30+F30 -> 60 | I30: 103383 | J30: C75-75 ECO ARU TRUSS
A31: DAK 54 / 4M | B31: 101031 | D31: 0 | G31: =D31-E31+F31 -> 0 | I31: 101031 | J31: DAK 54 / 4M
A32: DAK 54 / 4M (RUSAK) | B32: 102269 | D32: -4 | G32: =D32-E32+F32 -> -4 | I32: 102269 | J32: DAK 54 / 4M (RUSAK)
A33: DYNABOLT 10 X 50 MARIO | B33: 101035 | D33: -146 | G33: =D33-E33+F33 -> -146 | I33: 101035 | J33: DYNABOLT 10 X 50 MARIO
A34: DYNABOLT 10 X 65 MARIO | B34: 101036 | D34: -452 | G34: =D34-E34+F34 -> -452 | I34: 101036 | J34: DYNABOLT 10 X 65 MARIO
A35: ELG 01 / 4 M | B35: 101038 | D35: 8 | G35: =D35-E35+F35 -> 8 | I35: 101038 | J35: ELG 01 / 4 M
A36: ELG 01 / 4 M (RUSAK) | B36: 102276 | D36: -11 | G36: =D36-E36+F36 -> -11 | I36: 102276 | J36: ELG 01 / 4 M (RUSAK)
A37: ELG 010 / 4 M | B37: 101039 | D37: 327 | E37: =VLOOKUP(B37,'Rincian Penerimaan Barang'!$G$2:$I$70,3,0) -> 160 | F37: =VLOOKUP(B37,'Rincian Pesanan Penjualan'!$O$2:$Q$142,3,0) -> 30 | G37: =D37-E37+F37 -> 197 | I37: 101039 | J37: ELG 010 / 4 M
A38: ELG 010 / 4 M (RUSAK) | B38: 102277 | D38: -10 | G38: =D38-E38+F38 -> -10 | I38: 102277 | J38: ELG 010 / 4 M (RUSAK)
A39: ELG 011 G / 4 M | B39: 101040 | D39: -10 | G39: =D39-E39+F39 -> -10 | I39: 101040 | J39: ELG 011 G / 4 M
A40: ELG 014 / 4 M | B40: 101043 | D40: 0 | G40: =D40-E40+F40 -> 0 | I40: 101043 | J40: ELG 014 / 4 M
A41: ELG 015 / 4 M | B41: 101044 | D41: 1 | F41: =VLOOKUP(B41,'Rincian Pesanan Penjualan'!$O$2:$Q$142,3,0) -> 40 | G41: =D41-E41+F41 -> 41 | I41: 101044 | J41: ELG 015 / 4 M
A42: ELG 015 / 4 M (RUSAK) | B42: 102282 | D42: -21 | G42: =D42-E42+F42 -> -21 | I42: 102282 | J42: ELG 015 / 4 M (RUSAK)
A43: ELG 016 / 4 M | B43: 101045 | D43: 0 | G43: =D43-E43+F43 -> 0 | I43: 101045 | J43: ELG 016 / 4 M
A44: ELG 016 / 4 M (RUSAK) | B44: 102283 | D44: -15 | G44: =D44-E44+F44 -> -15 | I44: 102283 | J44: ELG 016 / 4 M (RUSAK)
A45: ELG 017 / 4 M | B45: 101046 | D45: 0 | G45: =D45-E45+F45 -> 0 | I45: 101046 | J45: ELG 017 / 4 M
A46: ELG 018 / 4 M | B46: 101047 | D46: -2 | G46: =D46-E46+F46 -> -2 | I46: 101047 | J46: ELG 018 / 4 M
A47: ELG 019 / 4 M | B47: 101048 | D47: -22 | G47: =D47-E47+F47 -> -22 | I47: 101048 | J47: ELG 019 / 4 M
...

Sheet Barang & Jasa
B1: Nama Barang | C1: Kode Barang | D1: Satuan | E1: Kuantitas
B2: ACP SEVEN QS3150 CHAMPAGNE GOLD METALIC | C2: 101993 | D2: LEMBAR
B3: ACP SEVEN QS3150 CHAMPAGNE GOLD METALIC (RIJECT) | C3: 301993 | D3: LEMBAR
B4: ACP SEVEN QS3150 CHAMPAGNE GOLD METALIC (RUSAK) | C4: 102181 | D4: LEMBAR
B5: ACP SEVEN QS8008 OLIVE BROWN | C5: 101992 | D5: LEMBAR
B6: ACP SEVEN QS8008 OLIVE BROWN (RIJECT) | C6: 301992 | D6: LEMBAR
B7: ACP SEVEN QS8008 OLIVE BROWN (RUSAK) | C7: 102182 | D7: LEMBAR
B8: ALUMINIUM DOUBLE P. 25M L. 1.20 | C8: 103432 | D8: ROLL
B9: ALUMINIUM DOUBLE P. 25M L. 1.20 (RIJECT) | C9: 303432 | D9: ROLL
B10: ARWANA DIGI FT 30X60 IMPREZA WT WARNA WHITE | C10: 101949 | D10: KOTAK
B11: ARWANA DIGI FT 30X60 IMPREZA WT WARNA WHITE (RIJECT) | C11: 301949 | D11: KOTAK
B12: ARWANA DIGI FT 30X60 IMPREZA WT WARNA WHITE (RUSAK) | C12: 102183 | D12: KOTAK
B13: ARWANA DIGI FT 40X40 EXP ALDRICH D.GREY | C13: 101892 | D13: KOTAK
... B4066: WPC TW 917 / 4M (RIJECT) | C4066: 303578 | D4066: LEMBAR

Sheet Sheet3
A1: Nama Barang | B1: RIJEK | D1: Nama Barang | E1: KODE BARANG
A2: ELG 011 G / 4 M | B2: 1 | D2: =A2 & " (RIJECT)" -> ELG 011 G / 4 M (RIJECT) | E2: =VLOOKUP(D2,$A$126:$B$1571,2,0) -> 301040 | F2: 1
A3: ELG 018 / 4 M | B3: 2 | D3: =A3 & " (RIJECT)" -> ELG 018 / 4 M (RIJECT) | E3: =VLOOKUP(D3,$A$126:$B$1571,2,0) -> 301047 | F3: 2
A4: ELG 020 / 4 M | B4: 2 | D4: =A4 & " (RIJECT)" -> ELG 020 / 4 M (RIJECT) | E4: =VLOOKUP(D4,$A$126:$B$1571,2,0) -> 301051 | F4: 2
A5: ELG 022 / 4 M | B5: 4 | D5: =A5 & " (RIJECT)" -> ELG 022 / 4 M (RIJECT) | E5: =VLOOKUP(D5,$A$126:$B$1571,2,0) -> 301053 | F5: 4
A6: ELG 025 / 4 M | B6: 6 | D6: =A6 & " (RIJECT)" -> ELG 025 / 4 M (RIJECT) | E6: =VLOOKUP(D6,$A$126:$B$1571,2,0) -> 301056 | F6: 6
A7: ELG 026 / 4 M | B7: 1 | D7: =A7 & " (RIJECT)" -> ELG 026 / 4 M (RIJECT) | E7: =VLOOKUP(D7,$A$126:$B$1571,2,0) -> 301057 | F7: 1
A8: ELG 030 / 4 M | B8: 1 | D8: =A8 & " (RIJECT)" -> ELG 030 / 4 M (RIJECT) | E8: =VLOOKUP(D8,$A$126:$B$1571,2,0) -> 301063 | F8: 1
A9: ELG 031 / 4 M | B9: 4 | D9: =A9 & " (RIJECT)" -> ELG 031 / 4 M (RIJECT) | E9: =VLOOKUP(D9,$A$126:$B$1571,2,0) -> 301064 | F9: 4
A10: ELG 037 / 4 M | B10: 1 | D10: =A10 & " (RIJECT)" -> ELG 037 / 4 M (RIJECT) | E10: =VLOOKUP(D10,$A$126:$B$1571,2,0) -> 301070 | F10: 1
A11: ELG 038 / 4 M | B11: 12 | D11: =A11 & " (RIJECT)" -> ELG 038 / 4 M (RIJECT) | E11: =VLOOKUP(D11,$A$126:$B$1571,2,0) -> 301071 | F11: 12
A12: ELG 039 / 4 M | B12: 4 | D12: =A12 & " (RIJECT)" -> ELG 039 / 4 M (RIJECT) | E12: =VLOOKUP(D12,$A$126:$B$1571,2,0) -> 301072 | F12: 4
A13: ELG 045 / 4 M | B13: 1 | D13: =A13 & " (RIJECT)" -> ELG 045 / 4 M (RIJECT) | E13: =VLOOKUP(D13,$A$126:$B$1571,2,0) -> 301080 | F13: 1
... A124: OR. 70 x 90 TIPE C | B124: 1 | D124: =A124 & " (RIJECT)" -> OR. 70 x 90 TIPE C (RIJECT) | E124: =VLOOKUP(D124,$A$126:$B$1571,2,0) -> 301619 | F124: 1
A126: ACP SEVEN QS3150 CHAMPAGNE GOLD METALIC (RIJECT) | B126: 301993
A127: ACP SEVEN QS8008 OLIVE BROWN (RIJECT) | B127: 301992
A128: ALUMINIUM DOUBLE P. 25M L. 1.20 (RIJECT) | B128: 303432
A129: ARWANA DIGI FT 30X60 IMPREZA WT WARNA WHITE (RIJECT) | B129: 301949
A130: ARWANA DIGI FT 40X40 EXP ALDRICH D.GREY (RIJECT) | B130: 301892
A131: ARWANA DIGI FT 40X40 EXP CONCORDIA DGREY (RIJECT) | B131: 301891
A132: ARWANA FT 40X40 EXP 99979 GREY (RIJECT) | B132: 301890
A133: ATAP 2 SSN BAMBU COKLAT GGROOF (RIJECT) | B133: 300968
A134: ATAP 2 SSN 0,25 HITAM CAKRA (RIJECT) | B134: 300969
A135: ATAP 2 SSN 0,25 TANPA PASIR MINIMALIS KOKOROOF COKLAT (RIJECT) | B135: 303557
A136: ATAP 2 SSN 0,25 TANPA PASIR MINIMALIS KOKOROOF HITAM (RIJECT) | B136: 303555
A137: ATAP 2 SSN 0.23 PRIMA MERAH MAS (RIJECT) | B137: 300970
... A1571: WPC TW 917 / 4M (RIJECT) | B1571: 303578
